Разберу каждый сценарий подробно, объясняя почему происходит NPE и как этого избежать:

## 1. Проблемы с цепочкой исключений (chained exceptions)

### Сценарий 1: Рекурсивная цепочка исключений
```java
try {
    Throwable t1 = new Throwable();
    Throwable t2 = new Throwable(t1);
    t1.initCause(t2); // Циклическая ссылка
    throw new RuntimeException(t1);
} catch (RuntimeException e) {
    e.printStackTrace(); // Может вызвать StackOverflowError или NPE при сериализации
}
```

**Почему происходит проблема:**
- Создается циклическая ссылка: t1 → t2 → t1
- При вызове `printStackTrace()` система пытается обойти всю цепочку причин
- Возникает бесконечная рекурсия или переполнение стека

**Что происходит внутри Throwable:**
```java
// В методе printEnclosedStackTrace()
private void printEnclosedStackTrace(..., Set<Throwable> dejaVu) {
    if (dejaVu.contains(this)) {
        s.println(prefix + caption + "[CIRCULAR REFERENCE: " + this + "]");
    } else {
        dejaVu.add(this);
        // Рекурсивный вызов для cause...
    }
}
```

**Как избежать:**
```java
// Правильно - проверять на циклические ссылки
public static void safeInitCause(Throwable target, Throwable cause) {
    // Проверяем всю цепочку причин
    Throwable current = cause;
    while (current != null) {
        if (current == target) {
            throw new IllegalArgumentException("Circular reference detected");
        }
        current = current.getCause();
    }
    target.initCause(cause);
}
```

### Сценарий 2: Исключение в методе toString() причины
```java
class BadException extends Exception {
    @Override
    public String toString() {
        String bad = null;
        return bad.length() + " error"; // NPE здесь
    }
}

try {
    throw new Exception(new BadException());
} catch (Exception e) {
    System.out.println(e.getCause()); // NPE при вызове toString()
}
```

**Почему происходит NPE:**
- `System.out.println(e.getCause())` неявно вызывает `toString()`
- В `BadException.toString()` происходит обращение к `null` ссылке
- NPE возникает в методе `toString()` исключения-причины

**Что происходит внутри:**
```java
// В printStackTrace()
s.println(this); // Вызывает toString() текущего исключения
// И для причин:
ourCause.printEnclosedStackTrace(...); // Тоже вызывает toString()
```

**Как избежать:**
```java
class SafeException extends Exception {
    @Override
    public String toString() {
        try {
            return "SafeException: " + super.getMessage();
        } catch (Exception e) {
            return "SafeException [error in toString: " + e.getMessage() + "]";
        }
    }
}

// Или при выводе:
try {
    Throwable cause = e.getCause();
    if (cause != null) {
        System.out.println("Cause: " + cause.getClass().getName());
        // Не вызываем toString() напрямую
    }
} catch (Exception ex) {
    System.out.println("Error printing cause: " + ex.getMessage());
}
```

## 2. Проблемы с подавленными исключениями

### Сценарий 3: Некорректная работа с подавленными исключениями
```java
try (BadResource br = new BadResource()) {
    throw new IOException("Main error");
} catch (IOException e) {
    e.printStackTrace(); // Может вызвать NPE
}
```

**Почему происходит NPE:**
- При использовании try-with-resources, если и в блоке try, и в close() возникают исключения
- Исключение из close() добавляется к подавленным (suppressed) основного исключения
- При выводе stack trace происходит обход подавленных исключений и вызов их `toString()`

**Что происходит внутри:**
```java
// В printStackTrace()
for (Throwable se : getSuppressed())
    se.printEnclosedStackTrace(s, trace, SUPPRESSED_CAPTION, "\t", dejaVu);
```

**Как избежать:**
```java
// Создавайте безопасные исключения для AutoCloseable
class SafeResource implements AutoCloseable {
    @Override
    public void close() {
        try {
            // код закрытия
        } catch (Exception e) {
            throw new SafeCloseException("Error closing resource", e);
        }
    }
}

class SafeCloseException extends RuntimeException {
    public SafeCloseException(String message, Throwable cause) {
        super(message, cause);
    }
    
    @Override
    public String toString() {
        return "SafeCloseException: " + getMessage(); // Безопасная реализация
    }
}
```

## 3. Проблемы сериализации/десериализации

### Сценарий 4: Поврежденная сериализация
```java
byte[] damagedData = baos.toByteArray();
damagedData[100] = 0; // Повреждаем данные
```

**Почему происходит NPE:**
- При десериализации метод `readObject()` валидирует данные
- Если в массиве `stackTrace` есть `null` элементы или повреждены другие поля
- Валидация выбрасывает NPE с понятным сообщением

**Что происходит внутри Throwable.readObject():**
```java
for (StackTraceElement ste : candidateStackTrace) {
    Objects.requireNonNull(ste, "null StackTraceElement in serial stream.");
    // Выбрасывает NPE если элемент null
}
```

**Как избежать:**
```java
// Используйте безопасную сериализацию
public class SafeSerialization {
    public static byte[] serialize(Throwable t) throws IOException {
        try (ByteArrayOutputStream baos = new ByteArrayOutputStream();
             ObjectOutputStream oos = new ObjectOutputStream(baos)) {
            oos.writeObject(t);
            return baos.toByteArray();
        }
    }
    
    public static Throwable deserialize(byte[] data) throws IOException, ClassNotFoundException {
        if (data == null || data.length == 0) {
            throw new IllegalArgumentException("Invalid serialized data");
        }
        try (ByteArrayInputStream bais = new ByteArrayInputStream(data);
             ObjectInputStream ois = new ObjectInputStream(bais)) {
            return (Throwable) ois.readObject();
        }
    }
}
```

## 4. Проблемы с пользовательскими исключениями

### Сценарий 5: Исключение в конструкторе
```java
class CustomException extends Exception {
    private static String staticField = null;
    
    public CustomException(String message) {
        super(message);
        this.instanceField = staticField.length(); // NPE здесь
    }
}
```

**Почему происходит NPE:**
- Статическое поле `staticField` инициализировано как `null`
- В конструкторе происходит обращение `staticField.length()`
- Исключение возникает ДО того как объект полностью создан

**Как избежать:**
```java
class SafeCustomException extends Exception {
    private static final String staticField = "";
    private final String instanceField;
    
    public SafeCustomException(String message) {
        super(message);
        // Инициализация после вызова super()
        this.instanceField = (staticField != null) ? staticField : "";
    }
    
    // Или ленивая инициализация
    private String getInstanceField() {
        return (instanceField != null) ? instanceField : "";
    }
}
```

## 5. Проблемы с рефлексией

### Сценарий 6: Нарушение инвариантов через рефлексию
```java
Field stackTraceField = Throwable.class.getDeclaredField("stackTrace");
stackTraceField.set(t, new StackTraceElement[]{null}); // null элемент
t.printStackTrace(); // NPE при обходе stackTrace
```

**Почему происходит NPE:**
- Рефлексия нарушает инварианты класса `Throwable`
- Метод `getOurStackTrace()` ожидает, что все элементы массива не-null
- При обходе массива возникает NPE

**Что происходит внутри:**
```java
private synchronized StackTraceElement[] getOurStackTrace() {
    // Возвращает массив, где могут быть null элементы
    // printStackTrace() пытается вызвать toString() для каждого элемента
}

// В printStackTrace()
for (StackTraceElement traceElement : trace)
    s.println("\tat " + traceElement); // traceElement может быть null
```

**Как избежать:**
```java
// Не используйте рефлексию для изменения внутреннего состояния исключений
// Если нужно кастомизировать stack trace, используйте официальный API:

public class SafeStackTrace {
    public static void setSafeStackTrace(Throwable t, StackTraceElement[] stackTrace) {
        // Валидация входных данных
        if (stackTrace != null) {
            for (StackTraceElement element : stackTrace) {
                if (element == null) {
                    throw new IllegalArgumentException("Stack trace elements cannot be null");
                }
            }
        }
        t.setStackTrace(stackTrace != null ? stackTrace : new StackTraceElement[0]);
    }
}
```

## 6. Многопоточные сценарии

### Сценарий 7: Гонка данных
```java
class ThreadUnsafeException extends Exception {
    private String volatileField;
    
    @Override
    public String getMessage() {
        return super.getMessage() + " - " + volatileField.length(); // NPE
    }
}
```

**Почему происходит NPE:**
- Один поток постоянно меняет `volatileField` между значением и `null`
- Другой поток в это время вызывает `getMessage()`
- В момент вызова `volatileField.length()` поле может быть `null`

**Как избежать:**
```java
class ThreadSafeException extends Exception {
    private final String immutableField; // final поле
    
    public ThreadSafeException(String message, String field) {
        super(message);
        this.immutableField = (field != null) ? field : "";
    }
    
    @Override
    public String getMessage() {
        return super.getMessage() + " - " + immutableField; // Безопасно
    }
}

// Или для изменяемых полей:
class SafeMutableException extends Exception {
    private volatile String safeField;
    
    public String getSafeMessage() {
        String field = safeField; // Копируем в локальную переменную
        return super.getMessage() + " - " + ((field != null) ? field : "");
    }
}
```

## 7. Проблемы с JVM/нативным кодом

### Сценарий 8: Исчерпание ресурсов
```java
while (true) {
    throwables.add(new Throwable("Memory pressure"));
}
```

**Почему может произойти NPE:**
- При исчерпании памяти JVM может находиться в нестабильном состоянии
- Нативный метод `fillInStackTrace()` может не получить доступ к стеку вызовов
- Внутренние структуры JVM могут быть повреждены

**Как избежать:**
```java
public class SafeThrowableCreator {
    public static Throwable createSafeThrowable(String message) {
        try {
            // Ограничиваем использование памяти для stack trace
            return new Throwable(message) {
                @Override
                public Throwable fillInStackTrace() {
                    // Используем легковесную версию
                    return this;
                }
            };
        } catch (OutOfMemoryError e) {
            // Возвращаем исключение без stack trace при нехватке памяти
            return new Throwable(message + " [stack trace unavailable due to OOM]");
        }
    }
}
```

## Общие рекомендации:

1. **Для цепочек исключений** - всегда проверяйте на циклические ссылки
2. **Для пользовательских исключений** - делайте методы `toString()` и `getMessage()` безопасными
3. **Для сериализации** - валидируйте данные перед десериализацией
4. **Для многопоточности** - используйте immutable объекты или proper synchronization
5. **Для ресурсов** - создавайте исключения с безопасными реализациями методов
6. **Всегда** предусматривайте обработку случаев, когда внутренние поля могут быть `null`

Эти практики помогут избежать NPE при работе с исключениями и сделают код более надежным.